Workbook

Sheet Consolidado
A1: Consolidado — Dia x Afiliado x Ação x Resultado
A2: Visão unificada de todas as ações e métricas, 10 a 16/06
A4: Data | B4: Afiliado | C4: Ação do Dia | D4: Observação | E4: Registros | F4: FTD | G4: CPA | H4: Comissão Rev. | I4: Comissão CPA | J4: Comissão Final
A5: 46183 | B5: Ah Maria | C5: Aposta Garantida NBA | E5: 5 | F5: 5 | G5: 5 | H5: -227.43 | I5: 970 | J5: 742.57
A6: 46183 | B6: Cabreloa | C6: Grupo grátis da Copa | E6: 4 | F6: 4 | G6: 4 | H6: 35.5999 | I6: 570 | J6: 605.5999
A7: 46183 | B7: Dupla Aposta | E7: 0 | F7: 0 | G7: 0 | H7: 58.07 | I7: 0 | J7: 58.07
A8: 46183 | B8: El Barba | C8: Vitória garantida (NBA - jogo 4) | E8: 82 | F8: 51 | G8: 44 | H8: 386.4641 | I8: 8290 | J8: 8676.4641
A9: 46183 | B9: Gol do Rayo | C9: Movimentação normal no grupo | E9: 62 | F9: 36 | G9: 17 | H9: 62.3398 | I9: 3850 | J9: 3912.3398
A10: 46183 | B10: Mateus Caumo | C10: Lançamento grupo da Copa | E10: 211 | F10: 174 | G10: 96 | H10: 95.3714 | I10: 15990 | J10: 16085.371
A11: 46183 | B11: Rennan | C11: Aposta Garantida (NBA) | E11: 26 | F11: 21 | G11: 18 | H11: 24.9021 | I11: 4150 | J11: 4174.9021
A12: 46183 | B12: Vitor ZZ | C12: Movimentação normal do grupo | E12: 16 | F12: 6 | G12: 4 | H12: -55.8413 | I12: 1020 | J12: 964.1587
A13: 46184 | B13: Ah Maria | C13: Movimentação normal (detalhe da aumentada que não acontecia) | E13: 5 | F13: 5 | G13: 7 | H13: 6.77 | I13: 1490 | J13: 1496.77
A14: 46184 | B14: Cabreloa | C14: Movimentação normal no grupo | E14: 13 | F14: 14 | G14: 11 | H14: 117.5483 | I14: 3040 | J14: 3157.5483
A15: 46184 | B15: Dupla Aposta | E15: 26 | F15: 12 | G15: 2 | H15: 61.61 | I15: 240 | J15: 301.61
A16: 46184 | B16: El Barba | C16: Aposta Garantida (México) | E16: 59 | F16: 54 | G16: 45 | H16: -55.5833 | I16: 11340 | J16: 11284.417
A17: 46184 | B17: Gol do Rayo | C17: Aposta Garantida (México) | E17: 292 | F17: 175 | G17: 109 | H17: 136.4906 | I17: 26640 | J17: 26776.491
A18: 46184 | B18: Mateus Caumo | C18: Bingão e movimento normal | E18: 268 | F18: 211 | G18: 190 | H18: 8398.5668 | I18: 33180 | J18: 41578.567
A19: 46184 | B19: Rennan | C19: Aposta Garantida (México) | E19: 34 | F19: 16 | G19: 13 | H19: 100.5761 | I19: 2840 | J19: 2940.5761
A20: 46184 | B20: Vitor ZZ | C20: Bingão, garantida (México), movimentação maior no grupo | E20: 118 | F20: 67 | G20: 30 | H20: 375.8946 | I20: 5450 | J20: 5825.8946
A21: 46185 | B21: Ah Maria | C21: Garantida do Brasil + aumentada | D21: Dia da restrição | E21: 84 | F21: 52 | G21: 46 | H21: 366.17 | I21: 11910 | J21: 12276.17
A22: 46185 | B22: Cabreloa | C22: Movimentação normal | D22: Dia da restrição | E22: 27 | F22: 21 | G22: 8 | H22: -58.8315 | I22: 1980 | J22: 1921.1685
A23: 46185 | B23: Dupla Aposta | E23: 3 | F23: 2 | G23: 1 | H23: -44.21 | I23: 120 | J23: 75.79
A24: 46185 | B24: El Barba | C24: Aposta garantida Vitória do Brasil | D24: Dia da restrição | E24: 40 | F24: 23 | G24: 20 | H24: 132.3506 | I24: 4720 | J24: 4852.3506
A25: 46185 | B25: Gol do Rayo | C25: Aposta Garantida (EUA) | D25: Dia da restrição | E25: 149 | F25: 81 | G25: 96 | H25: 46.63 | I25: 21170 | J25: 21216.63
A26: 46185 | B26: Mateus Caumo | C26: Movimentação normal no grupo | D26: Dia da restrição | E26: 64 | F26: 61 | G26: 79 | H26: -2220.8665 | I26: 15990 | J26: 13769.133
A27: 46185 | B27: Rennan | C27: Aposta Garantida (EUA) | D27: Dia da restrição | E27: 20 | F27: 7 | G27: 9 | H27: -38.0419 | I27: 2290 | J27: 2251.9581
A28: 46185 | B28: Vitor ZZ | C28: Bingão da Copa e movimento normal | D28: Dia da restrição | E28: 48 | F28: 28 | G28: 18 | H28: -47.1376 | I28: 4570 | J28: 4522.8624
A29: 46186 | B29: Ah Maria | C29: Aumentada esportiva + reforço da garantida do Brasil | E29: 10 | F29: 9 | G29: 3 | H29: 351.66 | I29: 500 | J29: 851.66
A30: 46186 | B30: Cabreloa | C30: Movimentação normal | E30: 51 | F30: 35 | G30: 22 | H30: 303.0504 | I30: 3190 | J30: 3493.0504
A31: 46186 | B31: Dupla Aposta | E31: 3 | F31: 4 | G31: 4 | H31: -231.9 | I31: 480 | J31: 248.1
A32: 46186 | B32: El Barba | C32: Lançou grupo da Copa | E32: 90 | F32: 73 | G32: 33 | H32: 1071.257 | I32: 6260 | J32: 7331.257
A33: 46186 | B33: Gol do Rayo | C33: Aposta Garantida Brasil | E33: 165 | F33: 117 | G33: 120 | H33: 1587.1283 | I33: 31450 | J33: 33037.128
A34: 46186 | B34: Mateus Caumo | C34: Movimentação normal no grupo | E34: 363 | F34: 314 | G34: 232 | H34: 20459.634 | I34: 36250 | J34: 56709.634
A35: 46186 | B35: Rennan | C35: Garantida do Brasil | E35: 50 | F35: 38 | G35: 41 | H35: 860.2323 | I35: 8960 | J35: 9820.2323
A36: 46186 | B36: Vitor ZZ | C36: Garantida do Brasil | E36: 59 | F36: 48 | G36: 44 | H36: 939.0678 | I36: 10740 | J36: 11679.068
A37: 46187 | B37: Ah Maria | C37: Aumentada e movimentação normal | E37: 11 | F37: 6 | G37: 5 | H37: 64.74 | I37: 880 | J37: 944.74
A38: 46187 | B38: Cabreloa | C38: Movimentação normal no grupo | E38: 27 | F38: 2 | G38: 9 | H38: 31.7152 | I38: 3280 | J38: 3311.7152
A39: 46187 | B39: Dupla Aposta | E39: 3 | F39: 2 | G39: 3 | H39: 324.5 | I39: 360 | J39: 684.5
A40: 46187 | B40: El Barba | C40: Movimentação normal no grupo (bingo) | E40: 29 | F40: 17 | G40: 20 | H40: 387.0349 | I40: 4570 | J40: 4957.0349
A41: 46187 | B41: Gol do Rayo | C41: Movimentação normal no grupo | E41: 41 | F41: 24 | G41: 37 | H41: 571.7975 | I41: 10220 | J41: 10791.798
...

Sheet Ah Maria Semanal
A1: Ah Maria
A2: Visão Semanal (7 dias) — Dados do Dashboard
A4: Campanha | B4: Master | C4: Casa | D4: Registros | E4: FTD | F4: CPA | G4: Comissão Rev. | H4: Comissão CPA | I4: Comissão Final
A5: mariatips | B5: Ah Maria | C5: MGM | D5: 90 | E5: 58 | F5: 51 | G5: 847.48 | H5: 13260 | I5: 14107.48
A6: mariatips | B6: Ah Maria | C6: ESPORTIVA BET | D6: 30 | E6: 19 | F6: 13 | G6: -196.14 | H6: 1560 | I6: 1363.86
A7: mariatips | B7: Ah Maria | C7: SUPERBET NOVO | D7: 2 | E7: 2 | F7: 2 | G7: 99.07 | H7: 700 | I7: 799.07
A8: Comercial04Mariatips | B8: Ah Maria | C8: SUPERBET NOVO | D8: 2 | E8: 2 | F8: 1 | G8: 103.7 | H8: 350 | I8: 453.7
A9: mariatips | B9: Ah Maria | C9: NOVIBET BC | D9: 6 | E9: 0 | F9: 1 | G9: 0 | H9: 395 | I9: 395
A10: Comercial01Mariatips | B10: Ah Maria | C10: MGM | D10: 0 | E10: 0 | F10: 0 | G10: 0 | H10: 0 | I10: 0
A11: Comercial02Mariatips | B11: Ah Maria | C11: MGM | D11: 0 | E11: 0 | F11: 0 | G11: 0 | H11: 0 | I11: 0
A12: Comercial03Mariatips | B12: Ah Maria | C12: MGM | D12: 0 | E12: 0 | F12: 0 | G12: 0 | H12: 0 | I12: 0
A13: Comercial04Mariatips | B13: Ah Maria | C13: MGM | D13: 0 | E13: 0 | F13: 0 | G13: 0 | H13: 0 | I13: 0
A14: Comercial05Mariatips | B14: Ah Maria | C14: MGM | D14: 0 | E14: 0 | F14: 0 | G14: 0 | H14: 0 | I14: 0
A15: mariatips | B15: Ah Maria | C15: NOVIBET | D15: 0 | E15: 0 | F15: 0 | G15: 0 | H15: 0 | I15: 0
A16: mariatips | B16: Ah Maria | C16: STAKE | D16: 0 | E16: 0 | F16: 0 | G16: 0 | H16: 0 | I16: 0
... A19: mariatipsboasvindas | B19: Ah Maria | C19: SUPERBET NOVO | D19: 0 | E19: 0 | F19: 0 | G19: 0 | H19: 0 | I19: 0
A45: Total | D45: =SUM(D5:D44) -> 131 | E45: =SUM(E5:E44) -> 82 | F45: =SUM(F5:F44) -> 68 | G45: =SUM(G5:G44) -> 854.11 | H45: =SUM(H5:H44) -> 16265 | I45: =SUM(I5:I44) -> 17119.11

Sheet Ah Maria Diário
A4: Data | B4: Campanha | C4: Master | D4: Casa | E4: Registros | F4: FTD | G4: CPA | H4: Comissão Rev. | I4: Comissão CPA | J4: Comissão Final
A5: 46183 | B5: mariatips | C5: Ah Maria | D5: SUPERBET NOVO | E5: 1 | F5: 1 | G5: 1 | H5: 1.33 | I5: 350 | J5: 351.33
A6: 46183 | B6: mariatips | C6: Ah Maria | D6: MGM | E6: 0 | F6: 1 | G6: 1 | H6: 9.45 | I6: 260 | J6: 269.45
A7: 46183 | B7: mariatips | C7: Ah Maria | D7: ESPORTIVA BET | E7: 4 | F7: 2 | G7: 3 | H7: -238.21 | I7: 360 | J7: 121.79
A8: 46183 | B8: Comercial01Mariatips | C8: Ah Maria | D8: MGM | E8: 0 | F8: 0 | G8: 0 | H8: 0 | I8: 0 | J8: 0
A9: 46183 | B9: Comercial02Mariatips | C9: Ah Maria | D9: MGM | E9: 0 | F9: 0 | G9: 0 | H9: 0 | I9: 0 | J9: 0
A10: 46183 | B10: Comercial03Mariatips | C10: Ah Maria | D10: MGM | E10: 0 | F10: 0 | G10: 0 | H10: 0 | I10: 0 | J10: 0
A11: 46183 | B11: Comercial04Mariatips | C11: Ah Maria | D11: MGM | E11: 0 | F11: 0 | G11: 0 | H11: 0 | I11: 0 | J11: 0
A12: 46183 | B12: Comercial05Mariatips | C12: Ah Maria | D12: MGM | E12: 0 | F12: 0 | G12: 0 | H12: 0 | I12: 0 | J12: 0
A13: 46183 | B13: mariatips | C13: Ah Maria | D13: NOVIBET | E13: 0 | F13: 0 | G13: 0 | H13: 0 | I13: 0 | J13: 0
A14: 46183 | B14: mariatips | C14: Ah Maria | D14: STAKE | E14: 0 | F14: 0 | G14: 0 | H14: 0 | I14: 0 | J14: 0
A15: 46183 | B15: mariatipsboasvindas | C15: Ah Maria | D15: MGM | E15: 0 | F15: 1 | G15: 0 | H15: 0 | I15: 0 | J15: 0
A16: 46183 | B16: mariatipsboasvindas | C16: Ah Maria | D16: SUPERBET NOVO | E16: 0 | F16: 0 | G16: 0 | H16: 0 | I16: 0 | J16: 0
A17: 46183 | B17: Subtotal do dia | E17: =SUM(E5:E16) -> 5 | F17: =SUM(F5:F16) -> 5 | G17: =SUM(G5:G16) -> 5 | H17: =SUM(H5:H16) -> -227.43 | I17: =SUM(I5:I16) -> 970 | J17: =SUM(J5:J16) -> 742.57
A19: 46184 | B19: mariatips | C19: Ah Maria | D19: MGM | E19: 3 | F19: 3 | G19: 3 | H19: -38.41 | I19: 780 | J19: 741.59
A20: 46184 | B20: Comercial04Mariatips | C20: Ah Maria | D20: SUPERBET NOVO | E20: 1 | F20: 1 | G20: 1 | H20: 20.38 | I20: 350 | J20: 370.38
A21: 46184 | B21: mariatips | C21: Ah Maria | D21: ESPORTIVA BET | E21: 1 | F21: 0 | G21: 3 | H21: -7.12 | I21: 360 | J21: 352.88
A22: 46184 | B22: mariatips | C22: Ah Maria | D22: SUPERBET NOVO | E22: 0 | F22: 1 | G22: 0 | H22: 31.92 | I22: 0 | J22: 31.92
A23: 46184 | B23: Comercial01Mariatips | C23: Ah Maria | D23: MGM | E23: 0 | F23: 0 | G23: 0 | H23: 0 | I23: 0 | J23: 0
A24: 46184 | B24: Comercial02Mariatips | C24: Ah Maria | D24: MGM | E24: 0 | F24: 0 | G24: 0 | H24: 0 | I24: 0 | J24: 0
A25: 46184 | B25: Comercial03Mariatips | C25: Ah Maria | D25: MGM | E25: 0 | F25: 0 | G25: 0 | H25: 0 | I25: 0 | J25: 0
A26: 46184 | B26: Comercial04Mariatips | C26: Ah Maria | D26: MGM | E26: 0 | F26: 0 | G26: 0 | H26: 0 | I26: 0 | J26: 0
A27: 46184 | B27: Comercial05Mariatips | C27: Ah Maria | D27: MGM | E27: 0 | F27: 0 | G27: 0 | H27: 0 | I27: 0 | J27: 0
A28: 46184 | B28: mariatipsboasvindas | C28: Ah Maria | D28: MGM | E28: 0 | F28: 0 | G28: 0 | H28: 0 | I28: 0 | J28: 0
A29: 46184 | B29: Subtotal do dia | E29: =SUM(E19:E28) -> 5 | F29: =SUM(F19:F28) -> 5 | G29: =SUM(G19:G28) -> 7 | H29: =SUM(H19:H28) -> 6.77 | I29: =SUM(I19:I28) -> 1490 | J29: =SUM(J19:J28) -> 1496.77
A31: 46185 | B31: mariatips | C31: Ah Maria | D31: MGM | E31: 81 | F31: 51 | G31: 44 | H31: 573.29 | I31: 11440 | J31: 12013.29
A32: 46185 | B32: mariatips | C32: Ah Maria | D32: SUPERBET NOVO | E32: 1 | F32: 0 | G32: 1 | H32: 10.22 | I32: 350 | J32: 360.22
A33: 46185 | B33: Comercial01Mariatips | C33: Ah Maria | D33: MGM | E33: 0 | F33: 0 | G33: 0 | H33: 0 | I33: 0 | J33: 0
A34: 46185 | B34: Comercial02Mariatips | C34: Ah Maria | D34: MGM | E34: 0 | F34: 0 | G34: 0 | H34: 0 | I34: 0 | J34: 0
A35: 46185 | B35: Comercial03Mariatips | C35: Ah Maria | D35: MGM | E35: 0 | F35: 0 | G35: 0 | H35: 0 | I35: 0 | J35: 0
A36: 46185 | B36: Comercial04Mariatips | C36: Ah Maria | D36: MGM | E36: 0 | F36: 0 | G36: 0 | H36: 0 | I36: 0 | J36: 0
A37: 46185 | B37: Comercial05Mariatips | C37: Ah Maria | D37: MGM | E37: 0 | F37: 0 | G37: 0 | H37: 0 | I37: 0 | J37: 0
A38: 46185 | B38: mariatipsboasvindas | C38: Ah Maria | D38: MGM | E38: 0 | F38: 0 | G38: 0 | H38: 0 | I38: 0 | J38: 0
A39: 46185 | B39: Comercial04Mariatips | C39: Ah Maria | D39: SUPERBET NOVO | E39: 0 | F39: 0 | G39: 0 | H39: -25.49 | I39: 0 | J39: -25.49
A40: 46185 | B40: mariatips | C40: Ah Maria | D40: ESPORTIVA BET | E40: 2 | F40: 1 | G40: 1 | H40: -191.85 | I40: 120 | J40: -71.85
A41: 46185 | B41: Subtotal do dia | E41: =SUM(E31:E40) -> 84 | F41: =SUM(F31:F40) -> 52 | G41: =SUM(G31:G40) -> 46 | H41: =SUM(H31:H40) -> 366.17 | I41: =SUM(I31:I40) -> 11910 | J41: =SUM(J31:J40) -> 12276.17
A43: 46186 | B43: mariatips | C43: Ah Maria | D43: MGM | E43: 0 | F43: 1 | G43: 1 | H43: 337.96 | I43: 260 | J43: 597.96
A44: 46186 | B44: mariatips | C44: Ah Maria | D44: ESPORTIVA BET | E44: 10 | F44: 8 | G44: 2 | H44: 6.05 | I44: 240 | J44: 246.05
A45: 46186 | B45: Comercial04Mariatips | C45: Ah Maria | D45: SUPERBET NOVO | E45: 0 | F45: 0 | G45: 0 | H45: 56.65 | I45: 0 | J45: 56.65
A46: 46186 | B46: Comercial01Mariatips | C46: Ah Maria | D46: MGM | E46: 0 | F46: 0 | G46: 0 | H46: 0 | I46: 0 | J46: 0
...

Sheet Ah Maria Ações
A1: Ah Maria
A2: Mapeamento de Ações de Promoção
A4: Data da Ação | B4: Campanha | C4: Tipo de Ação | D4: Canal | E4: Observações
A5: 46183 | C5: Aposta Garantida NBA
A6: 46184 | C6: Movimentação normal (detalhe da aumentada que não acontecia)
A7: 46185 | C7: Garantida do Brasil + aumentada | E7: Dia da restrição
A8: 46186 | C8: Aumentada esportiva + reforço da garantida do Brasil
A9: 46187 | C9: Aumentada e movimentação normal
A10: 46188 | C10: Movimentação normal no grupo
A11: 46189 | C11: Movimentação normal

Sheet Ah Maria Total
A1: Ah Maria
A2: Conferência — Diário vs Semanal
A4: Métrica | B4: Total Diário (acumulado) | C4: Total Semanal (dashboard) | D4: Diferença
A5: Registros | B5: ='Ah Maria Diário'!E17+'Ah Maria Diário'!E29+'Ah Maria Diário'!E41+'Ah Maria Diário'!E54+'Ah Maria Diário'!E68+'Ah Maria Diário'!E82+'Ah Maria Diário'!E97 -> 131 | C5: =SUM('Ah Maria Semanal'!D5:D44) -> 131 | D5: =B5-C5 -> 0
A6: FTD | B6: ='Ah Maria Diário'!F17+'Ah Maria Diário'!F29+'Ah Maria Diário'!F41+'Ah Maria Diário'!F54+'Ah Maria Diário'!F68+'Ah Maria Diário'!F82+'Ah Maria Diário'!F97 -> 82 | C6: =SUM('Ah Maria Semanal'!E5:E44) -> 82 | D6: =B6-C6 -> 0
A7: CPA | B7: ='Ah Maria Diário'!G17+'Ah Maria Diário'!G29+'Ah Maria Diário'!G41+'Ah Maria Diário'!G54+'Ah Maria Diário'!G68+'Ah Maria Diário'!G82+'Ah Maria Diário'!G97 -> 68 | C7: =SUM('Ah Maria Semanal'!F5:F44) -> 68 | D7: =B7-C7 -> 0
A8: Comissão Rev. | B8: ='Ah Maria Diário'!H17+'Ah Maria Diário'!H29+'Ah Maria Diário'!H41+'Ah Maria Diário'!H54+'Ah Maria Diário'!H68+'Ah Maria Diário'!H82+'Ah Maria Diário'!H97 -> 854.12 | C8: =SUM('Ah Maria Semanal'!G5:G44) -> 854.11 | D8: =B8-C8 -> 0.01
A9: Comissão CPA | B9: ='Ah Maria Diário'!I17+'Ah Maria Diário'!I29+'Ah Maria Diário'!I41+'Ah Maria Diário'!I54+'Ah Maria Diário'!I68+'Ah Maria Diário'!I82+'Ah Maria Diário'!I97 -> 16265 | C9: =SUM('Ah Maria Semanal'!H5:H44) -> 16265 | D9: =B9-C9 -> 0
A10: Comissão Final | B10: ='Ah Maria Diário'!J17+'Ah Maria Diário'!J29+'Ah Maria Diário'!J41+'Ah Maria Diário'!J54+'Ah Maria Diário'!J68+'Ah Maria Diário'!J82+'Ah Maria Diário'!J97 -> 17119.12 | C10: =SUM('Ah Maria Semanal'!I5:I44) -> 17119.11 | D10: =B10-C10 -> 0.01

Sheet Cabreloa Semanal
A1: Cabreloa
A2: Visão Semanal (7 dias) — Dados do Dashboard
A4: Campanha | B4: Master | C4: Casa | D4: Registros | E4: FTD | F4: CPA | G4: Comissão Rev. | H4: Comissão CPA | I4: Comissão Final
A5: cabreloa | B5: Cabreloa | C5: MGM | D5: 31 | E5: 26 | F5: 17 | G5: 330.66 | H5: 4420 | I5: 4750.66
A6: cabreloa | B6: Cabreloa | C6: SUPERBET NOVO | D6: 14 | E6: 12 | F6: 9 | G6: -23.51 | H6: 3150 | I6: 3126.49
A7: cabreloa | B7: Cabreloa | C7: STAKE BC | D7: 21 | F7: 6 | G7: 0 | H7: 2370 | I7: 2370
A8: Caiocabral | B8: Cabreloa | C8: ESPORTIVA BET | D8: 39 | E8: 28 | F8: 16 | G8: 7.36 | H8: 1920 | I8: 1927.36
A9: cabreloa | B9: Cabreloa | C9: NOVIBET BC | D9: 4 | F9: 2 | G9: 0 | H9: 790 | I9: 790
A10: cabreloa | B10: Cabreloa | C10: NOVIBET | D10: 8 | E10: 7 | F10: 2 | G10: 104.03 | H10: 420 | I10: 524.03
A11: cabreloa | B11: Cabreloa | C11: APOSTA GANHA | D11: 9 | E11: 6 | F11: 3 | G11: 33.34 | H11: 360 | I11: 393.34
A12: Comercial02Cabreloa | B12: Cabreloa | C12: ESPORTIVA BET | D12: 0 | E12: 0 | F12: 2 | G12: 17.08 | H12: 240 | I12: 257.08
A13: Comercial01Cabreloa | B13: Cabreloa | C13: ESPORTIVA BET | D13: 2 | E13: 2 | F13: 2 | G13: 14.06 | H13: 240 | I13: 254.06
A14: Comercial05Cabreloa | B14: Cabreloa | C14: ESPORTIVA BET | D14: 1 | E14: 1 | F14: 2 | G14: -6.43 | H14: 240 | I14: 233.57
A15: Comercial01Cabreloa | B15: Cabreloa | C15: NOVIBET | D15: 1 | E15: 1 | F15: 1 | G15: 16.9 | H15: 210 | I15: 226.9
A16: Comercial01Cabreloa | B16: Cabreloa | C16: APOSTA GANHA | D16: 3 | E16: 3 | F16: 1 | G16: 14.88 | H16: 120 | I16: 134.88
A17: Comercial01Cabreloa | B17: Cabreloa | C17: SUPERBET NOVO | D17: 0 | E17: 0 | F17: 0 | G17: 6.42 | H17: 0 | I17: 6.42
A18: cabreloaboasvindas | B18: Cabreloa | C18: MGM | D18: 0 | E18: 0 | F18: 0 | G18: 0 | H18: 0 | I18: 0
A19: Caiocabral | B19: Cabreloa | C19: STAKE | D19: 0 | E19: 0 | F19: 0 | G19: 0 | H19: 0 | I19: 0
A20: Comercial01Cabreloa | B20: Cabreloa | C20: MGM | D20: 0 | E20: 0 | F20: 0 | G20: 0 | H20: 0 | I20: 0
A21: Comercial02Cabreloa | B21: Cabreloa | C21: MGM | D21: 0 | E21: 0 | F21: 0 | G21: 0 | H21: 0 | I21: 0
... A30: Comercial05Cabreloa | B30: Cabreloa | C30: MGM | D30: 0 | E30: 0 | F30: 0 | G30: 0 | H30: 0 | I30: 0
A45: Total | D45: =SUM(D5:D44) -> 134 | E45: =SUM(E5:E44) -> 87 | F45: =SUM(F5:F44) -> 63 | G45: =SUM(G5:G44) -> 514.79 | H45: =SUM(H5:H44) -> 14480 | I45: =SUM(I5:I44) -> 14994.79

Sheet Cabreloa Diário
A1: Cabreloa
A2: Visão Diária — Dados do Dashboard
A4: Data | B4: Campanha | C4: Master | D4: Casa | E4: Registros | F4: FTD | G4: CPA | H4: Comissão Rev. | I4: Comissão CPA | J4: Comissão Final
A5: 46183 | B5: cabreloa | C5: Cabreloa | D5: NOVIBET | E5: 1 | F5: 1 | G5: 1 | H5: 105.6704 | I5: 210 | J5: 315.6704
A6: 46183 | B6: cabreloa | C6: Cabreloa | D6: SUPERBET NOVO | E6: 1 | F6: 1 | G6: 0 | H6: -5.068 | I6: 0 | J6: -5.068
A7: 46183 | B7: Caiocabral | C7: Cabreloa | D7: ESPORTIVA BET | E7: 1 | F7: 1 | G7: 1 | H7: -57.78 | I7: 120 | J7: 62.22
A8: 46183 | B8: Comercial05Cabreloa | C8: Cabreloa | D8: ESPORTIVA BET | E8: 1 | F8: 1 | G8: 0 | H8: 0 | I8: 0 | J8: 0
A9: 46183 | B9: cabreloa | C9: Cabreloa | D9: MGM | E9: 0 | F9: 0 | G9: 0 | H9: -13.0935 | I9: 0 | J9: -13.0935
A10: 46183 | B10: cabreloaboasvindas | C10: Cabreloa | D10: MGM | E10: 0 | F10: 0 | G10: 0 | H10: 0 | I10: 0 | J10: 0
A11: 46183 | B11: Caiocabral | C11: Cabreloa | D11: STAKE | E11: 0 | F11: 0 | G11: 0 | H11: 0 | I11: 0 | J11: 0
A12: 46183 | B12: Comercial01Cabreloa | C12: Cabreloa | D12: MGM | E12: 0 | F12: 0 | G12: 0 | H12: 0 | I12: 0 | J12: 0
A13: 46183 | B13: Comercial01Cabreloa | C13: Cabreloa | D13: SUPERBET NOVO | E13: 0 | F13: 0 | G13: 0 | H13: -4.029 | I13: 0 | J13: -4.029
A14: 46183 | B14: Comercial02Cabreloa | C14: Cabreloa | D14: ESPORTIVA BET | E14: 0 | F14: 0 | G14: 2 | H14: 9.9 | I14: 240 | J14: 249.9
A15: 46183 | B15: Comercial02Cabreloa | C15: Cabreloa | D15: MGM | E15: 0 | F15: 0 | G15: 0 | H15: 0 | I15: 0 | J15: 0
A16: 46183 | B16: Comercial03Cabreloa | C16: Cabreloa | D16: MGM | E16: 0 | F16: 0 | G16: 0 | H16: 0 | I16: 0 | J16: 0
... A20: 46183 | B20: Comercial05Cabreloa | C20: Cabreloa | D20: MGM | E20: 0 | F20: 0 | G20: 0 | H20: 0 | I20: 0 | J20: 0
A21: 46183 | B21: Subtotal do dia | E21: =SUM(E5:E20) -> 4 | F21: =SUM(F5:F20) -> 4 | G21: =SUM(G5:G20) -> 4 | H21: =SUM(H5:H20) -> 35.5999 | I21: =SUM(I5:I20) -> 570 | J21: =SUM(J5:J20) -> 605.5999
A23: 46184 | B23: cabreloa | C23: Cabreloa | D23: MGM | E23: 9 | F23: 8 | G23: 9 | H23: 83.4785 | I23: 2340 | J23: 2423.4785
A24: 46184 | B24: cabreloa | C24: Cabreloa | D24: SUPERBET NOVO | E24: 2 | F24: 4 | G24: 2 | H24: 42.3667 | I24: 700 | J24: 742.3667
A25: 46184 | B25: cabreloa | C25: Cabreloa | D25: NOVIBET | E25: 1 | F25: 1 | G25: 0 | H25: -6.2624 | I25: 0 | J25: -6.2624
A26: 46184 | B26: Comercial04Cabreloa | C26: Cabreloa | D26: ESPORTIVA BET | E26: 1 | F26: 1 | G26: 0 | H26: 0 | I26: 0 | J26: 0
A27: 46184 | B27: cabreloaboasvindas | C27: Cabreloa | D27: MGM | E27: 0 | F27: 0 | G27: 0 | H27: 0 | I27: 0 | J27: 0
A28: 46184 | B28: Caiocabral | C28: Cabreloa | D28: ESPORTIVA BET | E28: 0 | F28: 0 | G28: 0 | H28: 1.06 | I28: 0 | J28: 1.06
A29: 46184 | B29: Comercial01Cabreloa | C29: Cabreloa | D29: MGM | E29: 0 | F29: 0 | G29: 0 | H29: 0 | I29: 0 | J29: 0
A30: 46184 | B30: Comercial01Cabreloa | C30: Cabreloa | D30: SUPERBET NOVO | E30: 0 | F30: 0 | G30: 0 | H30: -3.0945 | I30: 0 | J30: -3.0945
A31: 46184 | B31: Comercial02Cabreloa | C31: Cabreloa | D31: ESPORTIVA BET | E31: 0 | F31: 0 | G31: 0 | H31: 0 | I31: 0 | J31: 0
A32: 46184 | B32: Comercial02Cabreloa | C32: Cabreloa | D32: MGM | E32: 0 | F32: 0 | G32: 0 | H32: 0 | I32: 0 | J32: 0
A33: 46184 | B33: Comercial03Cabreloa | C33: Cabreloa | D33: MGM | E33: 0 | F33: 0 | G33: 0 | H33: 0 | I33: 0 | J33: 0
A34: 46184 | B34: Comercial04Cabreloa | C34: Cabreloa | D34: MGM | E34: 0 | F34: 0 | G34: 0 | H34: 0 | I34: 0 | J34: 0
A35: 46184 | B35: Comercial05Cabreloa | C35: Cabreloa | D35: MGM | E35: 0 | F35: 0 | G35: 0 | H35: 0 | I35: 0 | J35: 0
A36: 46184 | B36: Subtotal do dia | E36: =SUM(E23:E35) -> 13 | F36: =SUM(F23:F35) -> 14 | G36: =SUM(G23:G35) -> 11 | H36: =SUM(H23:H35) -> 117.5483 | I36: =SUM(I23:I35) -> 3040 | J36: =SUM(J23:J35) -> 3157.5483
A38: 46185 | B38: cabreloa | C38: Cabreloa | D38: MGM | E38: 9 | F38: 8 | G38: 4 | H38: 44.2155 | I38: 1040 | J38: 1084.2155
A39: 46185 | B39: cabreloa | C39: Cabreloa | D39: SUPERBET NOVO | E39: 9 | F39: 5 | G39: 2 | H39: -108.8371 | I39: 700 | J39: 591.1629
A40: 46185 | B40: cabreloa | C40: Cabreloa | D40: NOVIBET | E40: 4 | F40: 3 | G40: 0 | H40: -5.2896 | I40: 0 | J40: -5.2896
A41: 46185 | B41: Comercial01Cabreloa | C41: Cabreloa | D41: APOSTA GANHA | E41: 3 | F41: 3 | G41: 1 | H41: 14.875 | I41: 120 | J41: 134.875
A42: 46185 | B42: Comercial01Cabreloa | C42: Cabreloa | D42: ESPORTIVA BET | E42: 1 | F42: 1 | G42: 1 | H42: 10.89 | I42: 120 | J42: 130.89
A43: 46185 | B43: Comercial01Cabreloa | C43: Cabreloa | D43: NOVIBET | E43: 1 | F43: 1 | G43: 0 | H43: -0.0608 | I43: 0 | J43: -0.0608
A44: 46185 | B44: cabreloaboasvindas | C44: Cabreloa | D44: MGM | E44: 0 | F44: 0 | G44: 0 | H44: 0 | I44: 0 | J44: 0
A45: 46185 | B45: Caiocabral | C45: Cabreloa | D45: ESPORTIVA BET | E45: 0 | F45: 0 | G45: 0 | H45: -1.65 | I45: 0 | J45: -1.65
A46: 46185 | B46: Comercial01Cabreloa | C46: Cabreloa | D46: MGM | E46: 0 | F46: 0 | G46: 0 | H46: 0 | I46: 0 | J46: 0
...

Sheet Cabreloa Ações
A1: Cabreloa
A2: Mapeamento de Ações de Promoção
A4: Data da Ação | B4: Campanha | C4: Tipo de Ação | D4: Canal | E4: Observações
A5: 46183 | C5: Grupo grátis da Copa
A6: 46184 | C6: Movimentação normal no grupo
A7: 46185 | C7: Movimentação normal | E7: Dia da restrição
A8: 46186 | C8: Movimentação normal
A9: 46187 | C9: Movimentação normal no grupo
A10: 46188 | C10: Movimentação normal no grupo
A11: 46189 | C11: Movimentação normal no grupo

Sheet Cabreloa Total
A1: Cabreloa
A2: Conferência — Diário vs Semanal
A4: Métrica | B4: Total Diário (acumulado) | C4: Total Semanal (dashboard) | D4: Diferença
A5: Registros | B5: ='Cabreloa Diário'!E21+'Cabreloa Diário'!E36+'Cabreloa Diário'!E53+'Cabreloa Diário'!E72+'Cabreloa Diário'!E88+'Cabreloa Diário'!E106+'Cabreloa Diário'!E122 -> 134 | C5: =SUM('Cabreloa Semanal'!D5:D44) -> 134 | D5: =B5-C5 -> 0
A6: FTD | B6: ='Cabreloa Diário'!F21+'Cabreloa Diário'!F36+'Cabreloa Diário'!F53+'Cabreloa Diário'!F72+'Cabreloa Diário'!F88+'Cabreloa Diário'!F106+'Cabreloa Diário'!F122 -> 87 | C6: =SUM('Cabreloa Semanal'!E5:E44) -> 87 | D6: =B6-C6 -> 0
A7: CPA | B7: ='Cabreloa Diário'!G21+'Cabreloa Diário'!G36+'Cabreloa Diário'!G53+'Cabreloa Diário'!G72+'Cabreloa Diário'!G88+'Cabreloa Diário'!G106+'Cabreloa Diário'!G122 -> 63 | C7: =SUM('Cabreloa Semanal'!F5:F44) -> 63 | D7: =B7-C7 -> 0
A8: Comissão Rev. | B8: ='Cabreloa Diário'!H21+'Cabreloa Diário'!H36+'Cabreloa Diário'!H53+'Cabreloa Diário'!H72+'Cabreloa Diário'!H88+'Cabreloa Diário'!H106+'Cabreloa Diário'!H122 -> 514.7937 | C8: =SUM('Cabreloa Semanal'!G5:G44) -> 514.79 | D8: =B8-C8 -> 0.0037
A9: Comissão CPA | B9: ='Cabreloa Diário'!I21+'Cabreloa Diário'!I36+'Cabreloa Diário'!I53+'Cabreloa Diário'!I72+'Cabreloa Diário'!I88+'Cabreloa Diário'!I106+'Cabreloa Diário'!I122 -> 14480 | C9: =SUM('Cabreloa Semanal'!H5:H44) -> 14480 | D9: =B9-C9 -> 0
A10: Comissão Final | B10: ='Cabreloa Diário'!J21+'Cabreloa Diário'!J36+'Cabreloa Diário'!J53+'Cabreloa Diário'!J72+'Cabreloa Diário'!J88+'Cabreloa Diário'!J106+'Cabreloa Diário'!J122 -> 14994.794 | C10: =SUM('Cabreloa Semanal'!I5:I44) -> 14994.79 | D10: =B10-C10 -> 0.0037

Sheet Dupla Aposta Semanal
A1: Dupla Aposta
A2: Visão Semanal (7 dias) — Dados do Dashboard
A4: Campanha | B4: Master | C4: Casa | D4: Registros | E4: FTD | F4: CPA | G4: Comissão Rev. | H4: Comissão CPA | I4: Comissão Final
A45: Total | D45: =SUM(D5:D44) -> 0 | E45: =SUM(E5:E44) -> 0 | F45: =SUM(F5:F44) -> 0 | G45: =SUM(G5:G44) -> 0 | H45: =SUM(H5:H44) -> 0 | I45: =SUM(I5:I44) -> 0

Sheet Dupla Aposta Diário
A1: Dupla Aposta
A2: Visão Diária — Dados do Dashboard
A4: Data | B4: Campanha | C4: Master | D4: Casa | E4: Registros | F4: FTD | G4: CPA | H4: Comissão Rev. | I4: Comissão CPA | J4: Comissão Final
A5: 46183 | B5: duplainstagram | C5: Dupla Aposta | D5: ESPORTIVA BET | E5: 0 | F5: 0 | G5: 0 | H5: 58.07 | I5: 0 | J5: 58.07
A6: 46183 | B6: Subtotal do dia | E6: =SUM(E5) -> 0 | F6: =SUM(F5) -> 0 | G6: =SUM(G5) -> 0 | H6: =SUM(H5) -> 58.07 | I6: =SUM(I5) -> 0 | J6: =SUM(J5) -> 58.07
A8: 46184 | B8: duplainstagram | C8: Dupla Aposta | D8: ESPORTIVA BET | E8: 26 | F8: 12 | G8: 2 | H8: 61.61 | I8: 240 | J8: 301.61
A9: 46184 | B9: Subtotal do dia | E9: =SUM(E8) -> 26 | F9: =SUM(F8) -> 12 | G9: =SUM(G8) -> 2 | H9: =SUM(H8) -> 61.61 | I9: =SUM(I8) -> 240 | J9: =SUM(J8) -> 301.61
A11: 46185 | B11: duplainstagram | C11: Dupla Aposta | D11: ESPORTIVA BET | E11: 3 | F11: 2 | G11: 1 | H11: -44.21 | I11: 120 | J11: 75.79
A12: 46185 | B12: Subtotal do dia | E12: =SUM(E11) -> 3 | F12: =SUM(F11) -> 2 | G12: =SUM(G11) -> 1 | H12: =SUM(H11) -> -44.21 | I12: =SUM(I11) -> 120 | J12: =SUM(J11) -> 75.79
A14: 46186 | B14: duplainstagram | C14: Dupla Aposta | D14: ESPORTIVA BET | E14: 3 | F14: 4 | G14: 4 | H14: -231.9 | I14: 480 | J14: 248.1
A15: 46186 | B15: Subtotal do dia | E15: =SUM(E14) -> 3 | F15: =SUM(F14) -> 4 | G15: =SUM(G14) -> 4 | H15: =SUM(H14) -> -231.9 | I15: =SUM(I14) -> 480 | J15: =SUM(J14) -> 248.1
A17: 46187 | B17: duplainstagram | C17: Dupla Aposta | D17: ESPORTIVA BET | E17: 3 | F17: 2 | G17: 3 | H17: 324.5 | I17: 360 | J17: 684.5
A18: 46187 | B18: Subtotal do dia | E18: =SUM(E17) -> 3 | F18: =SUM(F17) -> 2 | G18: =SUM(G17) -> 3 | H18: =SUM(H17) -> 324.5 | I18: =SUM(I17) -> 360 | J18: =SUM(J17) -> 684.5
A20: 46188 | B20: duplainstagram | C20: Dupla Aposta | D20: ESPORTIVA BET | E20: 1 | F20: 0 | G20: 0 | H20: 29.28 | I20: 0 | J20: 29.28
A21: 46188 | B21: Subtotal do dia | E21: =SUM(E20) -> 1 | F21: =SUM(F20) -> 0 | G21: =SUM(G20) -> 0 | H21: =SUM(H20) -> 29.28 | I21: =SUM(I20) -> 0 | J21: =SUM(J20) -> 29.28
A23: 46189 | B23: duplainstagram | C23: Dupla Aposta | D23: ESPORTIVA BET | E23: 6 | F23: 4 | G23: 3 | H23: 61.97 | I23: 360 | J23: 421.97
A24: 46189 | B24: Subtotal do dia | E24: =SUM(E23) -> 6 | F24: =SUM(F23) -> 4 | G24: =SUM(G23) -> 3 | H24: =SUM(H23) -> 61.97 | I24: =SUM(I23) -> 360 | J24: =SUM(J23) -> 421.97

Sheet Dupla Aposta Ações
A1: Dupla Aposta
A2: Mapeamento de Ações de Promoção
A4: Data da Ação | B4: Campanha | C4: Tipo de Ação | D4: Canal | E4: Observações

Sheet Dupla Aposta Total
A1: Dupla Aposta
A2: Conferência — Diário vs Semanal
A4: Métrica | B4: Total (dados do arquivo, 7 dias)
A5: Registros | B5: ='Dupla Aposta Diário'!E6+'Dupla Aposta Diário'!E9+'Dupla Aposta Diário'!E12+'Dupla Aposta Diário'!E15+'Dupla Aposta Diário'!E18+'Dupla Aposta Diário'!E21+'Dupla Aposta Diário'!E24 -> 42
A6: FTD | B6: ='Dupla Aposta Diário'!F6+'Dupla Aposta Diário'!F9+'Dupla Aposta Diário'!F12+'Dupla Aposta Diário'!F15+'Dupla Aposta Diário'!F18+'Dupla Aposta Diário'!F21+'Dupla Aposta Diário'!F24 -> 24
A7: CPA | B7: ='Dupla Aposta Diário'!G6+'Dupla Aposta Diário'!G9+'Dupla Aposta Diário'!G12+'Dupla Aposta Diário'!G15+'Dupla Aposta Diário'!G18+'Dupla Aposta Diário'!G21+'Dupla Aposta Diário'!G24 -> 13
A8: Comissão Rev. | B8: ='Dupla Aposta Diário'!H6+'Dupla Aposta Diário'!H9+'Dupla Aposta Diário'!H12+'Dupla Aposta Diário'!H15+'Dupla Aposta Diário'!H18+'Dupla Aposta Diário'!H21+'Dupla Aposta Diário'!H24 -> 259.32
A9: Comissão CPA | B9: ='Dupla Aposta Diário'!I6+'Dupla Aposta Diário'!I9+'Dupla Aposta Diário'!I12+'Dupla Aposta Diário'!I15+'Dupla Aposta Diário'!I18+'Dupla Aposta Diário'!I21+'Dupla Aposta Diário'!I24 -> 1560
A10: Comissão Final | B10: ='Dupla Aposta Diário'!J6+'Dupla Aposta Diário'!J9+'Dupla Aposta Diário'!J12+'Dupla Aposta Diário'!J15+'Dupla Aposta Diário'!J18+'Dupla Aposta Diário'!J21+'Dupla Aposta Diário'!J24 -> 1819.32

Sheet El Barba Semanal
A1: El Barba
A2: Visão Semanal (7 dias) — Dados do Dashboard
A4: Campanha | B4: Master | C4: Casa | D4: Registros | E4: FTD | F4: CPA | G4: Comissão Rev. | H4: Comissão CPA | I4: Comissão Final
A45: Total | D45: =SUM(D5:D44) -> 0 | E45: =SUM(E5:E44) -> 0 | F45: =SUM(F5:F44) -> 0 | G45: =SUM(G5:G44) -> 0 | H45: =SUM(H5:H44) -> 0 | I45: =SUM(I5:I44) -> 0

Sheet El Barba Diário
A1: El Barba
A2: Visão Diária — Dados do Dashboard
A4: Data | B4: Campanha | C4: Master | D4: Casa | E4: Registros | F4: FTD | G4: CPA | H4: Comissão Rev. | I4: Comissão CPA | J4: Comissão Final
A5: 46183 | B5: Barbaarena | C5: El Barba | D5: SPORTINGBET | E5: 2 | F5: 1 | G5: 0 | H5: 0.36 | I5: 0 | J5: 0.36
A6: 46183 | B6: Barbaarena | C6: El Barba | D6: SUPERBET OTG | E6: 0 | F6: 0 | G6: 0 | H6: -89.82 | I6: 0 | J6: -89.82
A7: 46183 | B7: barbabingaodacopa | C7: El Barba | D7: MGM | E7: 0 | F7: 0 | G7: 0 | H7: 0 | I7: 0 | J7: 0
A8: 46183 | B8: barbaboasvindas | C8: El Barba | D8: MGM | E8: 0 | F8: 0 | G8: 0 | H8: 0 | I8: 0 | J8: 0
A9: 46183 | B9: BarbaTipsLT | C9: El Barba | D9: SPORTINGBET | E9: 1 | F9: 0 | G9: 0 | H9: 0.39 | I9: 0 | J9: 0.39
A10: 46183 | B10: Comercial01_barba | C10: El Barba | D10: MGM | E10: 27 | F10: 12 | G10: 9 | H10: -56.77 | I10: 2340 | J10: 2283.23
A11: 46183 | B11: Comercial02_barba | C11: El Barba | D11: MGM | E11: 0 | F11: 0 | G11: 0 | H11: -4.739 | I11: 0 | J11: -4.739
A12: 46183 | B12: Comercial03_barba | C12: El Barba | D12: MGM | E12: 0 | F12: 0 | G12: 0 | H12: 0 | I12: 0 | J12: 0
A13: 46183 | B13: Comercial04_barba | C13: El Barba | D13: MGM | E13: 11 | F13: 2 | G13: 1 | H13: 20.405 | I13: 260 | J13: 280.405
A14: 46183 | B14: Comercial04Elbarba | C14: El Barba | D14: JONBET | E14: 0 | F14: 0 | G14: 0 | H14: -0.3 | I14: 0 | J14: -0.3
A15: 46183 | B15: Comercial05_barba | C15: El Barba | D15: MGM | E15: 0 | F15: 0 | G15: 0 | H15: 0 | I15: 0 | J15: 0
A16: 46183 | B16: Comercial06_barba | C16: El Barba | D16: MGM | E16: 0 | F16: 0 | G16: 0 | H16: 0 | I16: 0 | J16: 0
... A43: 46183 | B43: Elbarbacomercial11 | C43: El Barba | D43: STAKE | E43: 0 | F43: 0 | G43: 0 | H43: 0 | I43: 0 | J43: 0
A44: 46183 | B44: Subtotal do dia | E44: =SUM(E5:E43) -> 82 | F44: =SUM(F5:F43) -> 51 | G44: =SUM(G5:G43) -> 44 | H44: =SUM(H5:H43) -> 386.4641 | I44: =SUM(I5:I43) -> 8290 | J44: =SUM(J5:J43) -> 8676.4641
A46: 46184 | B46: barbabingaodacopa | C46: El Barba | D46: MGM | E46: 0 | F46: 0 | G46: 0 | H46: 0 | I46: 0 | J46: 0
A47: 46184 | B47: barbaboasvindas | C47: El Barba | D47: MGM | E47: 0 | F47: 0 | G47: 0 | H47: 0 | I47: 0 | J47: 0
A48: 46184 | B48: Comercial01_barba | C48: El Barba | D48: MGM | E48: 41 | F48: 39 | G48: 32 | H48: -142.4115 | I48: 8320 | J48: 8177.5885
A49: 46184 | B49: Comercial02_barba | C49: El Barba | D49: MGM | E49: 0 | F49: 2 | G49: 3 | H49: 67.9 | I49: 780 | J49: 847.9
A50: 46184 | B50: Comercial03_barba | C50: El Barba | D50: MGM | E50: 0 | F50: 0 | G50: 0 | H50: 0 | I50: 0 | J50: 0
A51: 46184 | B51: Comercial04_barba | C51: El Barba | D51: MGM | E51: 9 | F51: 3 | G51: 2 | H51: 20.8215 | I51: 520 | J51: 540.8215
A52: 46184 | B52: Comercial04Elbarba | C52: El Barba | D52: JONBET | E52: 0 | F52: 0 | G52: 0 | H52: 0.3 | I52: 0 | J52: 0.3
A53: 46184 | B53: Comercial05_barba | C53: El Barba | D53: MGM | E53: 0 | F53: 0 | G53: 0 | H53: 0 | I53: 0 | J53: 0
A54: 46184 | B54: Comercial06_barba | C54: El Barba | D54: MGM | E54: 0 | F54: 0 | G54: 0 | H54: -6.153 | I54: 0 | J54: -6.153
A55: 46184 | B55: Comercial07_barba | C55: El Barba | D55: MGM | E55: 0 | F55: 0 | G55: 0 | H55: 0 | I55: 0 | J55: 0
A56: 46184 | B56: Comercial08_barba | C56: El Barba | D56: MGM | E56: 0 | F56: 0 | G56: 0 | H56: 3.15 | I56: 0 | J56: 3.15
A57: 46184 | B57: Comercial09_barba | C57: El Barba | D57: MGM | E57: 0 | F57: 0 | G57: 0 | H57: 3.8255 | I57: 0 | J57: 3.8255
... A75: 46184 | B75: Elbarbacomercial03 | C75: El Barba | D75: ESPORTIVA BET | E75: 1 | F75: 1 | G75: 0 | H75: 15.3 | I75: 0 | J75: 15.3
A76: 46184 | B76: Subtotal do dia | E76: =SUM(E46:E75) -> 59 | F76: =SUM(F46:F75) -> 54 | G76: =SUM(G46:G75) -> 45 | H76: =SUM(H46:H75) -> -55.5833 | I76: =SUM(I46:I75) -> 11340 | J76: =SUM(J46:J75) -> 11284.417
A78: 46185 | B78: barbabingaodacopa | C78: El Barba | D78: MGM | E78: 0 | F78: 0 | G78: 0 | H78: 0 | I78: 0 | J78: 0
A79: 46185 | B79: barbaboasvindas | C79: El Barba | D79: MGM | E79: 0 | F79: 0 | G79: 0 | H79: 0 | I79: 0 | J79: 0
A80: 46185 | B80: Comercial01_barba | C80: El Barba | D80: MGM | E80: 23 | F80: 11 | G80: 7 | H80: -73.4055 | I80: 1820 | J80: 1746.5945
A81: 46185 | B81: Comercial02_barba | C81: El Barba | D81: MGM | E81: 0 | F81: 0 | G81: 0 | H81: 334.7995 | I81: 0 | J81: 334.7995
A82: 46185 | B82: Comercial03_barba | C82: El Barba | D82: MGM | E82: 0 | F82: 0 | G82: 0 | H82: 0 | I82: 0 | J82: 0
A83: 46185 | B83: Comercial04_barba | C83: El Barba | D83: MGM | E83: 11 | F83: 6 | G83: 4 | H83: -5.908 | I83: 1040 | J83: 1034.092
A84: 46185 | B84: Comercial05_barba | C84: El Barba | D84: MGM | E84: 0 | F84: 0 | G84: 0 | H84: 0 | I84: 0 | J84: 0
A85: 46185 | B85: Comercial06_barba | C85: El Barba | D85: MGM | E85: 0 | F85: 1 | G85: 0 | H85: -0.0315 | I85: 0 | J85: -0.0315
A86: 46185 | B86: Comercial07_barba | C86: El Barba | D86: MGM | E86: 1 | F86: 0 | G86: 0 | H86: 0 | I86: 0 | J86: 0
...

Sheet El Barba Ações
A1: El Barba
A2: Mapeamento de Ações de Promoção
A4: Data da Ação | B4: Campanha | C4: Tipo de Ação | D4: Canal | E4: Observações
A5: 46183 | C5: Vitória garantida (NBA - jogo 4)
A6: 46184 | C6: Aposta Garantida (México)
A7: 46185 | C7: Aposta garantida Vitória do Brasil | E7: Dia da restrição
A8: 46186 | C8: Lançou grupo da Copa
A9: 46187 | C9: Movimentação normal no grupo (bingo)
A10: 46188 | C10: Movimentação normal no grupo (bingo)
A11: 46189 | C11: Lançamento BETGO (2 bingos garantidos)

Sheet El Barba Total
A1: El Barba
A2: Conferência — Diário vs Semanal
A4: Métrica | B4: Total (dados do arquivo, 7 dias)
A5: Registros | B5: ='El Barba Diário'!E44+'El Barba Diário'!E76+'El Barba Diário'!E106+'El Barba Diário'!E138+'El Barba Diário'!E171+'El Barba Diário'!E201+'El Barba Diário'!E233 -> 759
A6: FTD | B6: ='El Barba Diário'!F44+'El Barba Diário'!F76+'El Barba Diário'!F106+'El Barba Diário'!F138+'El Barba Diário'!F171+'El Barba Diário'!F201+'El Barba Diário'!F233 -> 533
A7: CPA | B7: ='El Barba Diário'!G44+'El Barba Diário'!G76+'El Barba Diário'!G106+'El Barba Diário'!G138+'El Barba Diário'!G171+'El Barba Diário'!G201+'El Barba Diário'!G233 -> 200
A8: Comissão Rev. | B8: ='El Barba Diário'!H44+'El Barba Diário'!H76+'El Barba Diário'!H106+'El Barba Diário'!H138+'El Barba Diário'!H171+'El Barba Diário'!H201+'El Barba Diário'!H233 -> 2930.0888
A9: Comissão CPA | B9: ='El Barba Diário'!I44+'El Barba Diário'!I76+'El Barba Diário'!I106+'El Barba Diário'!I138+'El Barba Diário'!I171+'El Barba Diário'!I201+'El Barba Diário'!I233 -> 42510
A10: Comissão Final | B10: ='El Barba Diário'!J44+'El Barba Diário'!J76+'El Barba Diário'!J106+'El Barba Diário'!J138+'El Barba Diário'!J171+'El Barba Diário'!J201+'El Barba Diário'!J233 -> 45440.089

Sheet Gol do Rayo Semanal
A1: Gol do Rayo
A2: Visão Semanal (7 dias) — Dados do Dashboard
A4: Campanha | B4: Master | C4: Casa | D4: Registros | E4: FTD | F4: CPA | G4: Comissão Rev. | H4: Comissão CPA | I4: Comissão Final
A45: Total | D45: =SUM(D5:D44) -> 0 | E45: =SUM(E5:E44) -> 0 | F45: =SUM(F5:F44) -> 0 | G45: =SUM(G5:G44) -> 0 | H45: =SUM(H5:H44) -> 0 | I45: =SUM(I5:I44) -> 0

Sheet Gol do Rayo Diário
A1: Gol do Rayo
A2: Visão Diária — Dados do Dashboard
A4: Data | B4: Campanha | C4: Master | D4: Casa | E4: Registros | F4: FTD | G4: CPA | H4: Comissão Rev. | I4: Comissão CPA | J4: Comissão Final
A5: 46183 | B5: Comecial04_rayo | C5: Gol do Rayo | D5: MGM | E5: 25 | F5: 8 | G5: 4 | H5: 6.0305 | I5: 1040 | J5: 1046.0305
A6: 46183 | B6: Comecial09_rayo | C6: Gol do Rayo | D6: MGM | E6: 0 | F6: 0 | G6: 0 | H6: 0 | I6: 0 | J6: 0
A7: 46183 | B7: Comecial10_rayo | C7: Gol do Rayo | D7: MGM | E7: 0 | F7: 0 | G7: 0 | H7: 0 | I7: 0 | J7: 0
A8: 46183 | B8: Comercial01_rayo | C8: Gol do Rayo | D8: MGM | E8: 6 | F8: 7 | G8: 5 | H8: -112.42 | I8: 1300 | J8: 1187.58
A9: 46183 | B9: Comercial03_rayo | C9: Gol do Rayo | D9: MGM | E9: 0 | F9: 0 | G9: 0 | H9: 0 | I9: 0 | J9: 0
A10: 46183 | B10: Comercial05_rayo | C10: Gol do Rayo | D10: MGM | E10: 0 | F10: 0 | G10: 0 | H10: 0 | I10: 0 | J10: 0
A11: 46183 | B11: Comercial06_rayo | C11: Gol do Rayo | D11: MGM | E11: 1 | F11: 0 | G11: 0 | H11: 0 | I11: 0 | J11: 0
A12: 46183 | B12: Comercial07_rayo | C12: Gol do Rayo | D12: MGM | E12: 0 | F12: 0 | G12: 0 | H12: 0 | I12: 0 | J12: 0
A13: 46183 | B13: Comercial08_rayo | C13: Gol do Rayo | D13: MGM | E13: 0 | F13: 0 | G13: 0 | H13: 0 | I13: 0 | J13: 0
A14: 46183 | B14: Comercial11_rayo | C14: Gol do Rayo | D14: MGM | E14: 0 | F14: 0 | G14: 0 | H14: 0 | I14: 0 | J14: 0
A15: 46183 | B15: Comercias02_rayo | C15: Gol do Rayo | D15: MGM | E15: 0 | F15: 0 | G15: 0 | H15: 22.729 | I15: 0 | J15: 22.729
A16: 46183 | B16: Gol do Rayo - Alavancagem | C16: Gol do Rayo | D16: NOVIBET | E16: 3 | F16: 3 | G16: 0 | H16: -24.6848 | I16: 0 | J16: -24.6848
... A35: 46183 | B35: RayoLT | C35: Gol do Rayo | D35: SPORTINGBET | E35: 0 | F35: 0 | G35: 0 | H35: 52.79 | I35: 0 | J35: 52.79
A36: 46183 | B36: Subtotal do dia | E36: =SUM(E5:E35) -> 62 | F36: =SUM(F5:F35) -> 36 | G36: =SUM(G5:G35) -> 17 | H36: =SUM(H5:H35) -> 62.3398 | I36: =SUM(I5:I35) -> 3850 | J36: =SUM(J5:J35) -> 3912.3398
A38: 46184 | B38: Comecial04_rayo | C38: Gol do Rayo | D38: MGM | E38: 44 | F38: 21 | G38: 10 | H38: -53.9455 | I38: 2600 | J38: 2546.0545
A39: 46184 | B39: Comecial09_rayo | C39: Gol do Rayo | D39: MGM | E39: 0 | F39: 0 | G39: 0 | H39: 0 | I39: 0 | J39: 0
A40: 46184 | B40: Comecial10_rayo | C40: Gol do Rayo | D40: MGM | E40: 0 | F40: 0 | G40: 0 | H40: 0 | I40: 0 | J40: 0
A41: 46184 | B41: Comercial01_rayo | C41: Gol do Rayo | D41: MGM | E41: 91 | F41: 55 | G41: 41 | H41: -125.1145 | I41: 10660 | J41: 10534.886
A42: 46184 | B42: Comercial03_rayo | C42: Gol do Rayo | D42: MGM | E42: 0 | F42: 0 | G42: 0 | H42: 0 | I42: 0 | J42: 0
A43: 46184 | B43: Comercial05_rayo | C43: Gol do Rayo | D43: MGM | E43: 0 | F43: 0 | G43: 0 | H43: 0 | I43: 0 | J43: 0
A44: 46184 | B44: Comercial06_rayo | C44: Gol do Rayo | D44: MGM | E44: 0 | F44: 0 | G44: 0 | H44: -1.7395 | I44: 0 | J44: -1.7395
A45: 46184 | B45: Comercial07_rayo | C45: Gol do Rayo | D45: MGM | E45: 0 | F45: 0 | G45: 0 | H45: 0 | I45: 0 | J45: 0
A46: 46184 | B46: Comercial08_rayo | C46: Gol do Rayo | D46: MGM | E46: 0 | F46: 0 | G46: 0 | H46: 0 | I46: 0 | J46: 0
A47: 46184 | B47: Comercial11_rayo | C47: Gol do Rayo | D47: MGM | E47: 0 | F47: 0 | G47: 0 | H47: 0 | I47: 0 | J47: 0
A48: 46184 | B48: Comercias02_rayo | C48: Gol do Rayo | D48: MGM | E48: 0 | F48: 0 | G48: 1 | H48: 3.7415 | I48: 260 | J48: 263.7415
A49: 46184 | B49: Gol do Rayo - Alavancagem | C49: Gol do Rayo | D49: NOVIBET | E49: 6 | F49: 4 | G49: 4 | H49: -167.3216 | I49: 840 | J49: 672.6784
... A64: 46184 | B64: rayoboasvindas | C64: Gol do Rayo | D64: MGM | E64: 0 | F64: 0 | G64: 0 | H64: 0 | I64: 0 | J64: 0
A65: 46184 | B65: Subtotal do dia | E65: =SUM(E38:E64) -> 292 | F65: =SUM(F38:F64) -> 175 | G65: =SUM(G38:G64) -> 109 | H65: =SUM(H38:H64) -> 136.4906 | I65: =SUM(I38:I64) -> 26640 | J65: =SUM(J38:J64) -> 26776.491
A67: 46185 | B67: Comecial04_rayo | C67: Gol do Rayo | D67: MGM | E67: 39 | F67: 13 | G67: 7 | H67: 74.0145 | I67: 1820 | J67: 1894.0145
A68: 46185 | B68: Comecial09_rayo | C68: Gol do Rayo | D68: MGM | E68: 0 | F68: 0 | G68: 0 | H68: 0 | I68: 0 | J68: 0
A69: 46185 | B69: Comecial10_rayo | C69: Gol do Rayo | D69: MGM | E69: 0 | F69: 0 | G69: 0 | H69: 0 | I69: 0 | J69: 0
A70: 46185 | B70: Comercial01_rayo | C70: Gol do Rayo | D70: MGM | E70: 15 | F70: 12 | G70: 21 | H70: 16.961 | I70: 5460 | J70: 5476.961
A71: 46185 | B71: Comercial03_rayo | C71: Gol do Rayo | D71: MGM | E71: 0 | F71: 0 | G71: 0 | H71: 0 | I71: 0 | J71: 0
A72: 46185 | B72: Comercial05_rayo | C72: Gol do Rayo | D72: MGM | E72: 0 | F72: 0 | G72: 0 | H72: 0 | I72: 0 | J72: 0
A73: 46185 | B73: Comercial06_rayo | C73: Gol do Rayo | D73: MGM | E73: 0 | F73: 0 | G73: 0 | H73: 0.987 | I73: 0 | J73: 0.987
A74: 46185 | B74: Comercial07_rayo | C74: Gol do Rayo | D74: MGM | E74: 0 | F74: 0 | G74: 0 | H74: 0 | I74: 0 | J74: 0
A75: 46185 | B75: Comercial08_rayo | C75: Gol do Rayo | D75: MGM | E75: 0 | F75: 0 | G75: 0 | H75: 0 | I75: 0 | J75: 0
...

Sheet Gol do Rayo Ações
A1: Gol do Rayo
A2: Mapeamento de Ações de Promoção
A4: Data da Ação | B4: Campanha | C4: Tipo de Ação | D4: Canal | E4: Observações
A5: 46183 | C5: Movimentação normal no grupo
A6: 46184 | C6: Aposta Garantida (México)
A7: 46185 | C7: Aposta Garantida (EUA) | E7: Dia da restrição
A8: 46186 | C8: Aposta Garantida Brasil
A9: 46187 | C9: Movimentação normal no grupo
A10: 46188 | C10: Movimentação normal no grupo
A11: 46189 | C11: Lançamento BETGO

Sheet Gol do Rayo Total
A1: Gol do Rayo
A2: Conferência — Diário vs Semanal
A4: Métrica | B4: Total (dados do arquivo, 7 dias)
A5: Registros | B5: ='Gol do Rayo Diário'!E36+'Gol do Rayo Diário'!E65+'Gol do Rayo Diário'!E93+'Gol do Rayo Diário'!E118+'Gol do Rayo Diário'!E145+'Gol do Rayo Diário'!E173+'Gol do Rayo Diário'!E201 -> 1075
A6: FTD | B6: ='Gol do Rayo Diário'!F36+'Gol do Rayo Diário'!F65+'Gol do Rayo Diário'!F93+'Gol do Rayo Diário'!F118+'Gol do Rayo Diário'!F145+'Gol do Rayo Diário'!F173+'Gol do Rayo Diário'!F201 -> 639
A7: CPA | B7: ='Gol do Rayo Diário'!G36+'Gol do Rayo Diário'!G65+'Gol do Rayo Diário'!G93+'Gol do Rayo Diário'!G118+'Gol do Rayo Diário'!G145+'Gol do Rayo Diário'!G173+'Gol do Rayo Diário'!G201 -> 435
A8: Comissão Rev. | B8: ='Gol do Rayo Diário'!H36+'Gol do Rayo Diário'!H65+'Gol do Rayo Diário'!H93+'Gol do Rayo Diário'!H118+'Gol do Rayo Diário'!H145+'Gol do Rayo Diário'!H173+'Gol do Rayo Diário'!H201 -> 4107.5774
A9: Comissão CPA | B9: ='Gol do Rayo Diário'!I36+'Gol do Rayo Diário'!I65+'Gol do Rayo Diário'!I93+'Gol do Rayo Diário'!I118+'Gol do Rayo Diário'!I145+'Gol do Rayo Diário'!I173+'Gol do Rayo Diário'!I201 -> 106630
A10: Comissão Final | B10: ='Gol do Rayo Diário'!J36+'Gol do Rayo Diário'!J65+'Gol do Rayo Diário'!J93+'Gol do Rayo Diário'!J118+'Gol do Rayo Diário'!J145+'Gol do Rayo Diário'!J173+'Gol do Rayo Diário'!J201 -> 110737.58

Sheet Mateus Caumo Semanal
A1: Mateus Caumo
A2: Visão Semanal (7 dias) — Dados do Dashboard
A4: Campanha | B4: Master | C4: Casa | D4: Registros | E4: FTD | F4: CPA | G4: Comissão Rev. | H4: Comissão CPA | I4: Comissão Final
A45: Total | D45: =SUM(D5:D44) -> 0 | E45: =SUM(E5:E44) -> 0 | F45: =SUM(F5:F44) -> 0 | G45: =SUM(G5:G44) -> 0 | H45: =SUM(H5:H44) -> 0 | I45: =SUM(I5:I44) -> 0

Sheet Mateus Caumo Diário
A1: Mateus Caumo
A2: Visão Diária — Dados do Dashboard
A4: Data | B4: Campanha | C4: Master | D4: Casa | E4: Registros | F4: FTD | G4: CPA | H4: Comissão Rev. | I4: Comissão CPA | J4: Comissão Final
A5: 46183 | B5: [MATEUS] CAUMOSTATS - NOVO | C5: Mateus Caumo | D5: MGM | E5: 1 | F5: 1 | G5: 0 | H5: 0 | I5: 0 | J5: 0
A6: 46183 | B6: [MATEUS] GIRO PREMIADO - NOVO | C6: Mateus Caumo | D6: MGM | E6: 0 | F6: 0 | G6: 0 | H6: -3.626 | I6: 0 | J6: -3.626
A7: 46183 | B7: [MATEUS] SEGUIDOR PREMIADO - NOVO | C7: Mateus Caumo | D7: MGM | E7: 0 | F7: 0 | G7: 0 | H7: 0 | I7: 0 | J7: 0
A8: 46183 | B8: [MATEUS] TELEGRAM - NOVO | C8: Mateus Caumo | D8: MGM | E8: 0 | F8: 1 | G8: 1 | H8: 20.9475 | I8: 260 | J8: 280.9475
A9: 46183 | B9: Bilhete_Pronto - Matheus Caumo | C9: Mateus Caumo | D9: MGM | E9: 0 | F9: 0 | G9: 0 | H9: 0 | I9: 0 | J9: 0
A10: 46183 | B10: bingaodacopa | C10: Mateus Caumo | D10: MGM | E10: 0 | F10: 0 | G10: 0 | H10: 0 | I10: 0 | J10: 0
A11: 46183 | B11: Caiomiranda | C11: Mateus Caumo | D11: MGM | E11: 0 | F11: 0 | G11: 0 | H11: 4.2 | I11: 0 | J11: 4.2
A12: 46183 | B12: CaumoStats | C12: Mateus Caumo | D12: ESPORTIVA BET | E12: 0 | F12: 0 | G12: 0 | H12: -5.4 | I12: 0 | J12: -5.4
A13: 46183 | B13: CaumoStats | C13: Mateus Caumo | D13: GALERA BET | E13: 0 | F13: 0 | G13: 0 | H13: 0 | I13: 0 | J13: 0
A14: 46183 | B14: CaumoStats | C14: Mateus Caumo | D14: STAKE | E14: 0 | F14: 0 | G14: 0 | H14: 0 | I14: 0 | J14: 0
A15: 46183 | B15: comercial01_caumo | C15: Mateus Caumo | D15: MGM | E15: 0 | F15: 0 | G15: 0 | H15: 0 | I15: 0 | J15: 0
A16: 46183 | B16: comercial02_caumo | C16: Mateus Caumo | D16: MGM | E16: 0 | F16: 0 | G16: 0 | H16: 0 | I16: 0 | J16: 0
... A83: 46183 | B83: Vip | C83: Mateus Caumo | D83: ESPORTIVA BET | E83: 40 | F83: 37 | G83: 21 | H83: 52.45 | I83: 2520 | J83: 2572.45
A84: 46183 | B84: Subtotal do dia | E84: =SUM(E5:E83) -> 211 | F84: =SUM(F5:F83) -> 174 | G84: =SUM(G5:G83) -> 96 | H84: =SUM(H5:H83) -> 95.3714 | I84: =SUM(I5:I83) -> 15990 | J84: =SUM(J5:J83) -> 16085.371
A86: 46184 | B86: [MATEUS] CAUMOSTATS - NOVO | C86: Mateus Caumo | D86: MGM | E86: 0 | F86: 1 | G86: 1 | H86: 0 | I86: 260 | J86: 260
A87: 46184 | B87: [MATEUS] GIRO PREMIADO - NOVO | C87: Mateus Caumo | D87: MGM | E87: 0 | F87: 0 | G87: 0 | H87: -27.986 | I87: 0 | J87: -27.986
A88: 46184 | B88: [MATEUS] SEGUIDOR PREMIADO - NOVO | C88: Mateus Caumo | D88: MGM | E88: 0 | F88: 0 | G88: 0 | H88: -0.861 | I88: 0 | J88: -0.861
A89: 46184 | B89: [MATEUS] TELEGRAM - NOVO | C89: Mateus Caumo | D89: MGM | E89: 0 | F89: 0 | G89: 1 | H89: -5.5125 | I89: 260 | J89: 254.4875
A90: 46184 | B90: Bilhete_Pronto - Matheus Caumo | C90: Mateus Caumo | D90: MGM | E90: 0 | F90: 0 | G90: 0 | H90: 0 | I90: 0 | J90: 0
A91: 46184 | B91: bingaodacopa | C91: Mateus Caumo | D91: MGM | E91: 6 | F91: 0 | G91: 0 | H91: 0 | I91: 0 | J91: 0
A92: 46184 | B92: Caiomiranda | C92: Mateus Caumo | D92: MGM | E92: 0 | F92: 0 | G92: 0 | H92: 17.5525 | I92: 0 | J92: 17.5525
A93: 46184 | B93: CaumoStats | C93: Mateus Caumo | D93: ESPORTIVA BET | E93: 1 | F93: 1 | G93: 0 | H93: 8.97 | I93: 0 | J93: 8.97
A94: 46184 | B94: CaumoStats | C94: Mateus Caumo | D94: GALERA BET | E94: 4 | F94: 3 | G94: 0 | H94: -2.07 | I94: 0 | J94: -2.07
A95: 46184 | B95: comercial01_caumo | C95: Mateus Caumo | D95: MGM | E95: 0 | F95: 0 | G95: 0 | H95: 0 | I95: 0 | J95: 0
A96: 46184 | B96: comercial02_caumo | C96: Mateus Caumo | D96: MGM | E96: 0 | F96: 0 | G96: 0 | H96: 0 | I96: 0 | J96: 0
A97: 46184 | B97: comercial03_caumo | C97: Mateus Caumo | D97: MGM | E97: 0 | F97: 0 | G97: 0 | H97: 0 | I97: 0 | J97: 0
... A141: 46184 | B141: Vip | C141: Mateus Caumo | D141: ESPORTIVA BET | E141: 31 | F141: 27 | G141: 38 | H141: 1269.35 | I141: 4560 | J141: 5829.35
A142: 46184 | B142: Subtotal do dia | E142: =SUM(E86:E141) -> 268 | F142: =SUM(F86:F141) -> 211 | G142: =SUM(G86:G141) -> 190 | H142: =SUM(H86:H141) -> 8398.5668 | I142: =SUM(I86:I141) -> 33180 | J142: =SUM(J86:J141) -> 41578.567
A144: 46185 | B144: [MATEUS] CAUMOSTATS - NOVO | C144: Mateus Caumo | D144: MGM | E144: 0 | F144: 0 | G144: 0 | H144: -1.463 | I144: 0 | J144: -1.463
A145: 46185 | B145: [MATEUS] GIRO PREMIADO - NOVO | C145: Mateus Caumo | D145: MGM | E145: 0 | F145: 0 | G145: 0 | H145: -35.315 | I145: 0 | J145: -35.315
A146: 46185 | B146: [MATEUS] SEGUIDOR PREMIADO - NOVO | C146: Mateus Caumo | D146: MGM | E146: 0 | F146: 0 | G146: 0 | H146: -1.092 | I146: 0 | J146: -1.092
A147: 46185 | B147: [MATEUS] TELEGRAM - NOVO | C147: Mateus Caumo | D147: MGM | E147: 0 | F147: 0 | G147: 0 | H147: -4.935 | I147: 0 | J147: -4.935
A148: 46185 | B148: Bilhete_Pronto - Matheus Caumo | C148: Mateus Caumo | D148: MGM | E148: 0 | F148: 0 | G148: 0 | H148: 0 | I148: 0 | J148: 0
A149: 46185 | B149: bingaodacopa | C149: Mateus Caumo | D149: MGM | E149: 0 | F149: 0 | G149: 0 | H149: 0 | I149: 0 | J149: 0
A150: 46185 | B150: Caiomiranda | C150: Mateus Caumo | D150: MGM | E150: 0 | F150: 0 | G150: 0 | H150: 2.0125 | I150: 0 | J150: 2.0125
A151: 46185 | B151: CaumoStats | C151: Mateus Caumo | D151: ESPORTIVA BET | E151: 1 | F151: 1 | G151: 0 | H151: 0 | I151: 0 | J151: 0
A152: 46185 | B152: CaumoStats | C152: Mateus Caumo | D152: GALERA BET | E152: 1 | F152: 0 | G152: 0 | H152: 0 | I152: 0 | J152: 0
...

Sheet Mateus Caumo Ações
A1: Mateus Caumo
A2: Mapeamento de Ações de Promoção
A4: Data da Ação | B4: Campanha | C4: Tipo de Ação | D4: Canal | E4: Observações
A5: 46183 | C5: Lançamento grupo da Copa
A6: 46184 | C6: Bingão e movimento normal
A7: 46185 | C7: Movimentação normal no grupo | E7: Dia da restrição
A8: 46186 | C8: Movimentação normal no grupo
A9: 46187 | C9: Movimentação normal no grupo
A10: 46188 | C10: Movimentação normal do grupo
A11: 46189 | C11: Lançamento BETGO

Sheet Mateus Caumo Total
A1: Mateus Caumo
A2: Conferência — Diário vs Semanal
A4: Métrica | B4: Total (dados do arquivo, 7 dias)
A5: Registros | B5: ='Mateus Caumo Diário'!E84+'Mateus Caumo Diário'!E142+'Mateus Caumo Diário'!E199+'Mateus Caumo Diário'!E259+'Mateus Caumo Diário'!E325+'Mateus Caumo Diário'!E391+'Mateus Caumo Diário'!E456 -> 2448
A6: FTD | B6: ='Mateus Caumo Diário'!F84+'Mateus Caumo Diário'!F142+'Mateus Caumo Diário'!F199+'Mateus Caumo Diário'!F259+'Mateus Caumo Diário'!F325+'Mateus Caumo Diário'!F391+'Mateus Caumo Diário'!F456 -> 1413
A7: CPA | B7: ='Mateus Caumo Diário'!G84+'Mateus Caumo Diário'!G142+'Mateus Caumo Diário'!G199+'Mateus Caumo Diário'!G259+'Mateus Caumo Diário'!G325+'Mateus Caumo Diário'!G391+'Mateus Caumo Diário'!G456 -> 989
A8: Comissão Rev. | B8: ='Mateus Caumo Diário'!H84+'Mateus Caumo Diário'!H142+'Mateus Caumo Diário'!H199+'Mateus Caumo Diário'!H259+'Mateus Caumo Diário'!H325+'Mateus Caumo Diário'!H391+'Mateus Caumo Diário'!H456 -> 35777.164
A9: Comissão CPA | B9: ='Mateus Caumo Diário'!I84+'Mateus Caumo Diário'!I142+'Mateus Caumo Diário'!I199+'Mateus Caumo Diário'!I259+'Mateus Caumo Diário'!I325+'Mateus Caumo Diário'!I391+'Mateus Caumo Diário'!I456 -> 215490
A10: Comissão Final | B10: ='Mateus Caumo Diário'!J84+'Mateus Caumo Diário'!J142+'Mateus Caumo Diário'!J199+'Mateus Caumo Diário'!J259+'Mateus Caumo Diário'!J325+'Mateus Caumo Diário'!J391+'Mateus Caumo Diário'!J456 -> 251267.16

Sheet Rennan Semanal
A1: Rennan
A2: Visão Semanal (7 dias) — Dados do Dashboard
A4: Campanha | B4: Master | C4: Casa | D4: Registros | E4: FTD | F4: CPA | G4: Comissão Rev. | H4: Comissão CPA | I4: Comissão Final
A45: Total | D45: =SUM(D5:D44) -> 0 | E45: =SUM(E5:E44) -> 0 | F45: =SUM(F5:F44) -> 0 | G45: =SUM(G5:G44) -> 0 | H45: =SUM(H5:H44) -> 0 | I45: =SUM(I5:I44) -> 0

Sheet Rennan Diário
A1: Rennan
A2: Visão Diária — Dados do Dashboard
A4: Data | B4: Campanha | C4: Master | D4: Casa | E4: Registros | F4: FTD | G4: CPA | H4: Comissão Rev. | I4: Comissão CPA | J4: Comissão Final
A5: 46183 | B5: Comercia03_renan | C5: Rennan | D5: MGM | E5: 0 | F5: 0 | G5: 0 | H5: -3.15 | I5: 0 | J5: -3.15
A6: 46183 | B6: Comercial01_renan | C6: Rennan | D6: MGM | E6: 12 | F6: 10 | G6: 9 | H6: -53.9525 | I6: 2340 | J6: 2286.0475
A7: 46183 | B7: Comercial01RennanBraganca | C7: Rennan | D7: JONBET | E7: 0 | F7: 0 | G7: 0 | H7: -0.06 | I7: 0 | J7: -0.06
A8: 46183 | B8: Comercial02_renan | C8: Rennan | D8: MGM | E8: 0 | F8: 0 | G8: 0 | H8: 0 | I8: 0 | J8: 0
A9: 46183 | B9: Comercial02RennanBraganca | C9: Rennan | D9: JONBET | E9: 0 | F9: 0 | G9: 0 | H9: 0 | I9: 0 | J9: 0
A10: 46183 | B10: Comercial03RennanBraganca | C10: Rennan | D10: JONBET | E10: 0 | F10: 0 | G10: 0 | H10: -0.06 | I10: 0 | J10: -0.06
A11: 46183 | B11: Comercial04_renan | C11: Rennan | D11: MGM | E11: 1 | F11: 1 | G11: 0 | H11: -9.2785 | I11: 0 | J11: -9.2785
A12: 46183 | B12: Comercial05_renan | C12: Rennan | D12: MGM | E12: 0 | F12: 0 | G12: 0 | H12: 0 | I12: 0 | J12: 0
A13: 46183 | B13: Comercial06_renan | C13: Rennan | D13: MGM | E13: 0 | F13: 0 | G13: 0 | H13: 0 | I13: 0 | J13: 0
A14: 46183 | B14: Comercial07_renan | C14: Rennan | D14: MGM | E14: 0 | F14: 0 | G14: 0 | H14: 0 | I14: 0 | J14: 0
A15: 46183 | B15: Comercial08_renan | C15: Rennan | D15: MGM | E15: 0 | F15: 0 | G15: 0 | H15: 0 | I15: 0 | J15: 0
A16: 46183 | B16: Comercial09_renan | C16: Rennan | D16: MGM | E16: 0 | F16: 0 | G16: 0 | H16: 0 | I16: 0 | J16: 0
... A37: 46183 | B37: rennnanboasvindas | C37: Rennan | D37: MGM | E37: 0 | F37: 0 | G37: 0 | H37: 0 | I37: 0 | J37: 0
A38: 46183 | B38: Subtotal do dia | E38: =SUM(E5:E37) -> 26 | F38: =SUM(F5:F37) -> 21 | G38: =SUM(G5:G37) -> 18 | H38: =SUM(H5:H37) -> 24.9021 | I38: =SUM(I5:I37) -> 4150 | J38: =SUM(J5:J37) -> 4174.9021
A40: 46184 | B40: Comercia03_renan | C40: Rennan | D40: MGM | E40: 0 | F40: 0 | G40: 1 | H40: -48.3945 | I40: 260 | J40: 211.6055
A41: 46184 | B41: Comercial01_renan | C41: Rennan | D41: MGM | E41: 6 | F41: 4 | G41: 3 | H41: -26.2745 | I41: 780 | J41: 753.7255
A42: 46184 | B42: Comercial02_renan | C42: Rennan | D42: MGM | E42: 0 | F42: 0 | G42: 0 | H42: 0 | I42: 0 | J42: 0
A43: 46184 | B43: Comercial04_renan | C43: Rennan | D43: MGM | E43: 7 | F43: 2 | G43: 0 | H43: 2.8875 | I43: 0 | J43: 2.8875
A44: 46184 | B44: Comercial05_renan | C44: Rennan | D44: MGM | E44: 0 | F44: 0 | G44: 0 | H44: 0 | I44: 0 | J44: 0
A45: 46184 | B45: Comercial06_renan | C45: Rennan | D45: MGM | E45: 0 | F45: 0 | G45: 0 | H45: 0 | I45: 0 | J45: 0
A46: 46184 | B46: Comercial07_renan | C46: Rennan | D46: MGM | E46: 0 | F46: 0 | G46: 0 | H46: 0 | I46: 0 | J46: 0
A47: 46184 | B47: Comercial08_renan | C47: Rennan | D47: MGM | E47: 0 | F47: 0 | G47: 0 | H47: 0 | I47: 0 | J47: 0
A48: 46184 | B48: Comercial09_renan | C48: Rennan | D48: MGM | E48: 0 | F48: 0 | G48: 0 | H48: 0 | I48: 0 | J48: 0
A49: 46184 | B49: Comercial10_renan | C49: Rennan | D49: MGM | E49: 0 | F49: 0 | G49: 0 | H49: 0 | I49: 0 | J49: 0
A50: 46184 | B50: Comercial11_renan | C50: Rennan | D50: MGM | E50: 0 | F50: 0 | G50: 0 | H50: 0 | I50: 0 | J50: 0
A51: 46184 | B51: Rennan Bragança - Alavancagem | C51: Rennan | D51: NOVIBET | E51: 7 | F51: 2 | G51: 2 | H51: 65.8464 | I51: 420 | J51: 485.8464
... A63: 46184 | B63: rennnanboasvindas | C63: Rennan | D63: MGM | E63: 0 | F63: 0 | G63: 0 | H63: 0 | I63: 0 | J63: 0
A64: 46184 | B64: Subtotal do dia | E64: =SUM(E40:E63) -> 34 | F64: =SUM(F40:F63) -> 16 | G64: =SUM(G40:G63) -> 13 | H64: =SUM(H40:H63) -> 100.5761 | I64: =SUM(I40:I63) -> 2840 | J64: =SUM(J40:J63) -> 2940.5761
A66: 46185 | B66: Comercia03_renan | C66: Rennan | D66: MGM | E66: 0 | F66: 0 | G66: 4 | H66: 40.999 | I66: 1040 | J66: 1080.999
A67: 46185 | B67: Comercial01_renan | C67: Rennan | D67: MGM | E67: 4 | F67: 1 | G67: 1 | H67: -6.559 | I67: 260 | J67: 253.441
A68: 46185 | B68: Comercial02_renan | C68: Rennan | D68: MGM | E68: 0 | F68: 0 | G68: 0 | H68: -0.8155 | I68: 0 | J68: -0.8155
A69: 46185 | B69: Comercial04_renan | C69: Rennan | D69: MGM | E69: 8 | F69: 4 | G69: 2 | H69: -5.586 | I69: 520 | J69: 514.414
A70: 46185 | B70: Comercial05_renan | C70: Rennan | D70: MGM | E70: 0 | F70: 0 | G70: 0 | H70: 0 | I70: 0 | J70: 0
A71: 46185 | B71: Comercial06_renan | C71: Rennan | D71: MGM | E71: 0 | F71: 0 | G71: 0 | H71: 0 | I71: 0 | J71: 0
A72: 46185 | B72: Comercial07_renan | C72: Rennan | D72: MGM | E72: 0 | F72: 0 | G72: 0 | H72: 0 | I72: 0 | J72: 0
A73: 46185 | B73: Comercial08_renan | C73: Rennan | D73: MGM | E73: 0 | F73: 0 | G73: 0 | H73: 0 | I73: 0 | J73: 0
A74: 46185 | B74: Comercial09_renan | C74: Rennan | D74: MGM | E74: 0 | F74: 0 | G74: 0 | H74: 0 | I74: 0 | J74: 0
...

Sheet Rennan Ações
A1: Rennan
A2: Mapeamento de Ações de Promoção
A4: Data da Ação | B4: Campanha | C4: Tipo de Ação | D4: Canal | E4: Observações
A5: 46183 | C5: Aposta Garantida (NBA)
A6: 46184 | C6: Aposta Garantida (México)
A7: 46185 | C7: Aposta Garantida (EUA) | E7: Dia da restrição
A8: 46186 | C8: Garantida do Brasil
A9: 46187 | C9: Movimentação normal no grupo
A10: 46188 | C10: Movimentação normal no grupo
A11: 46189 | C11: Lançamento BETGO (bingo garantido)

Sheet Rennan Total
A1: Rennan
A2: Conferência — Diário vs Semanal
A4: Métrica | B4: Total (dados do arquivo, 7 dias)
A5: Registros | B5: ='Rennan Diário'!E38+'Rennan Diário'!E64+'Rennan Diário'!E89+'Rennan Diário'!E113+'Rennan Diário'!E136+'Rennan Diário'!E158+'Rennan Diário'!E180 -> 336
A6: FTD | B6: ='Rennan Diário'!F38+'Rennan Diário'!F64+'Rennan Diário'!F89+'Rennan Diário'!F113+'Rennan Diário'!F136+'Rennan Diário'!F158+'Rennan Diário'!F180 -> 211
A7: CPA | B7: ='Rennan Diário'!G38+'Rennan Diário'!G64+'Rennan Diário'!G89+'Rennan Diário'!G113+'Rennan Diário'!G136+'Rennan Diário'!G158+'Rennan Diário'!G180 -> 103
A8: Comissão Rev. | B8: ='Rennan Diário'!H38+'Rennan Diário'!H64+'Rennan Diário'!H89+'Rennan Diário'!H113+'Rennan Diário'!H136+'Rennan Diário'!H158+'Rennan Diário'!H180 -> 1129.8786
A9: Comissão CPA | B9: ='Rennan Diário'!I38+'Rennan Diário'!I64+'Rennan Diário'!I89+'Rennan Diário'!I113+'Rennan Diário'!I136+'Rennan Diário'!I158+'Rennan Diário'!I180 -> 22440
A10: Comissão Final | B10: ='Rennan Diário'!J38+'Rennan Diário'!J64+'Rennan Diário'!J89+'Rennan Diário'!J113+'Rennan Diário'!J136+'Rennan Diário'!J158+'Rennan Diário'!J180 -> 23569.879

Sheet Vitor ZZ Semanal
A1: Vitor ZZ
A2: Visão Semanal (7 dias) — Dados do Dashboard
A4: Campanha | B4: Master | C4: Casa | D4: Registros | E4: FTD | F4: CPA | G4: Comissão Rev. | H4: Comissão CPA | I4: Comissão Final
A45: Total | D45: =SUM(D5:D44) -> 0 | E45: =SUM(E5:E44) -> 0 | F45: =SUM(F5:F44) -> 0 | G45: =SUM(G5:G44) -> 0 | H45: =SUM(H5:H44) -> 0 | I45: =SUM(I5:I44) -> 0

Sheet Vitor ZZ Diário
A1: Vitor ZZ
A2: Visão Diária — Dados do Dashboard
A4: Data | B4: Campanha | C4: Master | D4: Casa | E4: Registros | F4: FTD | G4: CPA | H4: Comissão Rev. | I4: Comissão CPA | J4: Comissão Final
A5: 46183 | B5: Comecial01_victor | C5: Vitor ZZ | D5: MGM | E5: 8 | F5: 1 | G5: 0 | H5: 26.8765 | I5: 0 | J5: 26.8765
A6: 46183 | B6: Comecial08_victor | C6: Vitor ZZ | D6: MGM | E6: 0 | F6: 0 | G6: 0 | H6: 0 | I6: 0 | J6: 0
A7: 46183 | B7: Comecial09_victor | C7: Vitor ZZ | D7: MGM | E7: 0 | F7: 0 | G7: 0 | H7: 0 | I7: 0 | J7: 0
A8: 46183 | B8: Comecial10_victor | C8: Vitor ZZ | D8: MGM | E8: 0 | F8: 0 | G8: 1 | H8: -1.197 | I8: 260 | J8: 258.803
A9: 46183 | B9: Comercial01VitorZz | C9: Vitor ZZ | D9: GALERA BET | E9: 0 | F9: 0 | G9: 0 | H9: 7.233 | I9: 0 | J9: 7.233
A10: 46183 | B10: Comercial02_victor | C10: Vitor ZZ | D10: MGM | E10: 0 | F10: 0 | G10: 0 | H10: -71.1235 | I10: 0 | J10: -71.1235
A11: 46183 | B11: Comercial03_victor | C11: Vitor ZZ | D11: MGM | E11: 0 | F11: 0 | G11: 0 | H11: -12.152 | I11: 0 | J11: -12.152
A12: 46183 | B12: Comercial04_victor | C12: Vitor ZZ | D12: MGM | E12: 0 | F12: 0 | G12: 0 | H12: 1.2075 | I12: 0 | J12: 1.2075
A13: 46183 | B13: Comercial05_victor | C13: Vitor ZZ | D13: MGM | E13: 1 | F13: 1 | G13: 0 | H13: 0 | I13: 0 | J13: 0
A14: 46183 | B14: Comercial05VitorZz | C14: Vitor ZZ | D14: GALERA BET | E14: 0 | F14: 0 | G14: 0 | H14: 0 | I14: 0 | J14: 0
A15: 46183 | B15: Comercial06_victor | C15: Vitor ZZ | D15: MGM | E15: 0 | F15: 0 | G15: 0 | H15: 0 | I15: 0 | J15: 0
A16: 46183 | B16: Comercial07_victor | C16: Vitor ZZ | D16: MGM | E16: 0 | F16: 1 | G16: 1 | H16: -21.1715 | I16: 260 | J16: 238.8285
... A45: 46183 | B45: Zzarena | C45: Vitor ZZ | D45: SUPERBET OTG | E45: 0 | F45: 0 | G45: 1 | H45: 32.43 | I45: 300 | J45: 332.43
A46: 46183 | B46: Subtotal do dia | E46: =SUM(E5:E45) -> 16 | F46: =SUM(F5:F45) -> 6 | G46: =SUM(G5:G45) -> 4 | H46: =SUM(H5:H45) -> -55.8413 | I46: =SUM(I5:I45) -> 1020 | J46: =SUM(J5:J45) -> 964.1587
A48: 46184 | B48: Comecial01_victor | C48: Vitor ZZ | D48: MGM | E48: 15 | F48: 9 | G48: 5 | H48: 82.586 | I48: 1300 | J48: 1382.586
A49: 46184 | B49: Comecial08_victor | C49: Vitor ZZ | D49: MGM | E49: 0 | F49: 0 | G49: 0 | H49: 0 | I49: 0 | J49: 0
A50: 46184 | B50: Comecial09_victor | C50: Vitor ZZ | D50: MGM | E50: 0 | F50: 0 | G50: 0 | H50: 0 | I50: 0 | J50: 0
A51: 46184 | B51: Comecial10_victor | C51: Vitor ZZ | D51: MGM | E51: 0 | F51: 0 | G51: 0 | H51: 3.99 | I51: 0 | J51: 3.99
